Workbook

Sheet Read Me
A1: Sonartra Signals WPLP-80 Full Report Model
A3: Purpose | B3: Manual validation workbook covering all 80 questions, scoring weights, thresholds, archetypes, and generated language outputs.
A4: How to use | B4: 1) Review Questions and Weights. 2) Enter A/B/C/D responses on Responses. 3) Review Results and Output. 4) Adjust weights, thresholds, or sentence logic as needed.
A5: Naming convention | B5: Operator replaces Stabiliser throughout the workbook for clearer business language.
A6: Source note | B6: Weightings are based on the existing Sonartra scoring model workbook and expanded here with Decision & Risk and Role Fit structures.

Sheet Questions
A1: Q# | B1: Section | C1: Question | D1: A Option | E1: B Option | F1: C Option | G1: D Option
A2: 1 | B2: Core Personality | C2: When beginning a new initiative, I usually: | D2: Start immediately and refine as I go | E2: Map out the plan in detail first | F2: Speak to key stakeholders before acting | G2: Wait for clarity and direction
A3: 2 | B3: Core Personality | C3: My natural energy level at work is: | D3: High and intense | E3: Consistent and steady | F3: Calm and reflective | G3: Variable depending on environment
A4: 3 | B4: Core Personality | C4: When priorities change suddenly: | D4: Adapt quickly | E4: Reassess methodically | F4: Check impact on others | G4: Feel unsettled
A5: 4 | B5: Core Personality | C5: I prefer tasks that are: | D5: Challenging and visible | E5: Structured and defined | F5: Collaborative | G5: Technical or analytical
A6: 5 | B6: Core Personality | C6: In uncertain situations I: | D6: Move forward confidently | E6: Gather more data | F6: Seek reassurance | G6: Maintain stability
A7: 6 | B7: Core Personality | C7: My attention to detail is: | D7: Secondary to momentum | E7: Balanced | F7: Very high | G7: Delegated where possible
A8: 7 | B8: Core Personality | C8: Feedback typically: | D8: Motivates me | E8: Helps refine performance | F8: Feels personal | G8: Must be logical to matter
A9: 8 | B9: Core Personality | C9: My decision-making style is: | D9: Fast | E9: Balanced | F9: Cautious | G9: Data-driven
A10: 9 | B10: Behaviour Style | C10: In meetings I tend to: | D10: Direct the discussion | E10: Generate ideas | F10: Support others | G10: Question assumptions
A11: 10 | B11: Behaviour Style | C11: My communication is: | D11: Direct and concise | E11: Persuasive and expressive | F11: Patient and empathetic | G11: Precise and factual
A12: 11 | B12: Behaviour Style | C12: When leading a project I: | D12: Set aggressive goals | E12: Inspire enthusiasm | F12: Ensure everyone feels included | G12: Focus on systems and accuracy
A13: 12 | B13: Behaviour Style | C13: Under time pressure I: | D13: Push harder | E13: Motivate the team | F13: Protect morale | G13: Double-check details
... A81: 80 | B81: Behavioural Integrity & Nuance | C81: When evaluating people’s performance I value most: | D81: Results delivered | E81: Influence created | F81: Relationships maintained | G81: Quality of thinking

Sheet Thresholds
A1: Measure | B1: Low Max | C1: Medium Max | D1: High Max | E1: Notes
A2: Normalised Score | B2: 0.33 | C2: 0.66 | D2: 1 | E2: Used for Low / Medium / High banding.
A3: Narrative Strong | B3: 0 | C3: 0 | D3: 0.75 | E3: Use strong sentence if score/share >= this threshold.
A4: Narrative Moderate | B4: 0 | C4: 0.55 | D4: 0.74 | E4: Use moderate sentence if score/share >= this threshold and < strong.
A5: Leadership Potential Strong | B5: 0 | C5: 0 | D5: 0.7 | E5: Composite threshold.
A6: Role Alignment Strong | B6: 0 | C6: 0 | D6: 0.7 | E6: Composite threshold.

Sheet Archetypes
A1: Primary | B1: Secondary | C1: Archetype | D1: Identity Sentence | E1: Key
A2: Driver | B2: Analyst | C2: Strategic Operator | D2: You are a decisive and structured operator who takes control quickly while grounding decisions in logic and analysis. | E2: =A2&"|"&B2 -> Driver|Analyst
A3: Driver | B3: Influencer | C3: Growth Leader | D3: You are an energetic, persuasive leader who creates momentum through confidence, visibility, and forward drive. | E3: =A3&"|"&B3 -> Driver|Influencer
A4: Driver | B4: Operator | C4: Execution Leader | D4: You are a controlled, delivery-focused leader who drives results while protecting consistency and operational reliability. | E4: =A4&"|"&B4 -> Driver|Operator
A5: Influencer | B5: Driver | C5: Persuasive Driver | D5: You are a charismatic, fast-moving achiever who influences others to build momentum and deliver outcomes. | E5: =A5&"|"&B5 -> Influencer|Driver
A6: Influencer | B6: Operator | C6: Culture Builder | D6: You are a relationship-focused connector who strengthens trust, morale, and cohesion across teams. | E6: =A6&"|"&B6 -> Influencer|Operator
A7: Influencer | B7: Analyst | C7: Communicating Strategist | D7: You are an articulate and thoughtful communicator who translates complexity into insight and direction. | E7: =A7&"|"&B7 -> Influencer|Analyst
A8: Analyst | B8: Driver | C8: Systems Commander | D8: You are a logical and performance-focused builder of systems, standards, and disciplined execution. | E8: =A8&"|"&B8 -> Analyst|Driver
A9: Analyst | B9: Operator | C9: Systems Architect | D9: You are a dependable, detail-focused architect of stable systems, reliable processes, and measured execution. | E9: =A9&"|"&B9 -> Analyst|Operator
A10: Operator | B10: Driver | C10: Operational Leader | D10: You are a dependable execution-focused leader who brings order, continuity, and disciplined follow-through to delivery. | E10: =A10&"|"&B10 -> Operator|Driver
A11: Operator | B11: Influencer | C11: People Operator | D11: You are a supportive, steady connector who keeps teams aligned, calm, and practically engaged. | E11: =A11&"|"&B11 -> Operator|Influencer
A12: Operator | B12: Analyst | C12: Reliability Architect | D12: You are a consistent, process-minded operator who protects quality, stability, and operational integrity. | E12: =A12&"|"&B12 -> Operator|Analyst
A13: Analyst | B13: Influencer | C13: Insight Translator | D13: You combine analysis with communication, helping others understand patterns, risks, and opportunities clearly. | E13: =A13&"|"&B13 -> Analyst|Influencer

Sheet Sentence Library
A1: Category | B1: Signal | C1: Band | D1: Sentence | E1: Key
A2: Core Identity | B2: Driver | C2: High | D2: You naturally take control and focus on outcomes. | E2: =A2&"|"&B2&"|"&C2 -> Core Identity|Driver|High
A3: Core Identity | B3: Influencer | C3: High | D3: You bring energy, engagement, and visibility into group environments. | E3: =A3&"|"&B3&"|"&C3 -> Core Identity|Influencer|High
A4: Core Identity | B4: Operator | C4: High | D4: You focus on consistent execution, reliability, and maintaining operational stability. | E4: =A4&"|"&B4&"|"&C4 -> Core Identity|Operator|High
A5: Core Identity | B5: Analyst | C5: High | D5: You rely on logic, structure, and evidence when making decisions. | E5: =A5&"|"&B5&"|"&C5 -> Core Identity|Analyst|High
A6: How You Operate | B6: Achievement | C6: High | D6: You are driven by measurable success and clear outcomes. | E6: =A6&"|"&B6&"|"&C6 -> How You Operate|Achievement|High
A7: How You Operate | B7: Influence | C7: High | D7: You are motivated by visibility, reach, and the ability to shape others thinking. | E7: =A7&"|"&B7&"|"&C7 -> How You Operate|Influence|High
A8: How You Operate | B8: Stability | C8: High | D8: You are motivated by security, continuity, and low-friction execution. | E8: =A8&"|"&B8&"|"&C8 -> How You Operate|Stability|High
A9: How You Operate | B9: Mastery | C9: High | D9: You are motivated by expertise, precision, and continual improvement. | E9: =A9&"|"&B9&"|"&C9 -> How You Operate|Mastery|High
A10: Leadership | B10: Results | C10: High | D10: You lead with a strong bias toward delivery, standards, and performance. | E10: =A10&"|"&B10&"|"&C10 -> Leadership|Results|High
A11: Leadership | B11: Vision | C11: High | D11: You lead by creating belief, momentum, and future direction. | E11: =A11&"|"&B11&"|"&C11 -> Leadership|Vision|High
A12: Leadership | B12: People | C12: High | D12: You lead by building trust, support, and team development. | E12: =A12&"|"&B12&"|"&C12 -> Leadership|People|High
A13: Leadership | B13: Process | C13: High | D13: You lead through clarity, structure, and system design. | E13: =A13&"|"&B13&"|"&C13 -> Leadership|Process|High
... A26: Culture | B26: Hierarchy | C26: High | D26: You are likely to thrive in structured, process-driven cultures. | E26: =A26&"|"&B26&"|"&C26 -> Culture|Hierarchy|High

Sheet Rule Engine
A1: Rule Type | B1: Condition | C1: Output
A2: Tension | B2: Driver high & Operator high | C2: You balance a desire for control with a need for stability, which can create friction in fast-changing environments.
A3: Tension | B3: Influencer high & Analyst high | C3: You combine communication and structured thinking, though you may shift between intuition and logic depending on context.
A4: Risk Modifier | B4: Driver high & Stress Control high | C4: Under strain, your drive for results can become over-control.
A5: Risk Modifier | B5: Analyst high & Stress Criticality high | C5: Under strain, your standards can harden into excessive criticism or over-analysis.
A6: Risk Modifier | B6: Operator high & Stress Avoidance high | C6: Under strain, your preference for stability can become withdrawal from difficult issues.
A7: Risk Modifier | B7: Influencer high & Stress Scatter high | C7: Under strain, your energy can become diffuse and less focused.

Sheet Weights
A1: Question | B1: Answer | C1: Key | D1: Question Text | E1: Reverse_Flag | F1: Style_Driver | G1: Style_Influencer | H1: Style_Operator | I1: Style_Analyst | J1: Mot_Achievement | K1: Mot_Influence | L1: Mot_Stability | M1: Mot_Mastery | N1: Lead_Results | O1: Lead_Vision | P1: Lead_People | Q1: Lead_Process | R1: Conflict_Compete | S1: Conflict_Collaborate | T1: Conflict_Compromise | U1: Conflict_Accommodate | V1: Conflict_Avoid | W1: Culture_Market | X1: Culture_Adhocracy | Y1: Culture_Clan | Z1: Culture_Hierarchy | AA1: Stress_Control | AB1: Stress_Scatter | AC1: Stress_Avoidance | AD1: Stress_Criticality | AE1: Decision_Agility | AF1: Decision_Consensus | AG1: Decision_Stability | AH1: Decision_Evidence | AI1: Role_Commercial Leadership | AJ1: Role_Business Development | AK1: Role_Operations Management | AL1: Role_Technical Specialist
A2: 1 | B2: A | C2: 1|A | D2: When beginning a new initiative, I usually: | E2: 0 | F2: 3 | G2: 0 | H2: 0 | I2: 0 | J2: 0.5 | K2: 0 | L2: 0 | M2: 0 | N2: 0.5 | O2: 0 | P2: 0 | Q2: 0 | R2: 0 | S2: 0 | T2: 0 | U2: 0 | V2: 0 | W2: 0 | X2: 0 | Y2: 0 | Z2: 0 | AA2: 0 | AB2: 0 | AC2: 0 | AD2: 0 | AE2: 0 | AF2: 0 | AG2: 0 | AH2: 0 | AI2: 0 | AJ2: 0 | AK2: 0 | AL2: 0
A3: 1 | B3: B | C3: 1|B | D3: When beginning a new initiative, I usually: | E3: 0 | F3: 0 | G3: 3 | H3: 0 | I3: 0 | J3: 0 | K3: 0.5 | L3: 0 | M3: 0 | N3: 0 | O3: 0.5 | P3: 0 | Q3: 0 | R3: 0 | S3: 0 | T3: 0 | U3: 0 | V3: 0 | W3: 0 | X3: 0 | Y3: 0 | Z3: 0 | AA3: 0 | AB3: 0 | AC3: 0 | AD3: 0 | AE3: 0 | AF3: 0 | AG3: 0 | AH3: 0 | AI3: 0 | AJ3: 0 | AK3: 0 | AL3: 0
A4: 1 | B4: C | C4: 1|C | D4: When beginning a new initiative, I usually: | E4: 0 | F4: 0 | G4: 0 | H4: 3 | I4: 0 | J4: 0 | K4: 0 | L4: 0.5 | M4: 0 | N4: 0 | O4: 0 | P4: 0.5 | Q4: 0 | R4: 0 | S4: 0 | T4: 0 | U4: 0 | V4: 0 | W4: 0 | X4: 0 | Y4: 0 | Z4: 0 | AA4: 0 | AB4: 0 | AC4: 0 | AD4: 0 | AE4: 0 | AF4: 0 | AG4: 0 | AH4: 0 | AI4: 0 | AJ4: 0 | AK4: 0 | AL4: 0
A5: 1 | B5: D | C5: 1|D | D5: When beginning a new initiative, I usually: | E5: 0 | F5: 0 | G5: 0 | H5: 0 | I5: 3 | J5: 0 | K5: 0 | L5: 0 | M5: 0.5 | N5: 0 | O5: 0 | P5: 0 | Q5: 0.5 | R5: 0 | S5: 0 | T5: 0 | U5: 0 | V5: 0 | W5: 0 | X5: 0 | Y5: 0 | Z5: 0 | AA5: 0 | AB5: 0 | AC5: 0 | AD5: 0 | AE5: 0 | AF5: 0 | AG5: 0 | AH5: 0 | AI5: 0 | AJ5: 0 | AK5: 0 | AL5: 0
A6: 2 | B6: A | C6: 2|A | D6: My natural energy level at work is: | E6: 0 | F6: 3 | G6: 0 | H6: 0 | I6: 0 | J6: 0.5 | K6: 0 | L6: 0 | M6: 0 | N6: 0.5 | O6: 0 | P6: 0 | Q6: 0 | R6: 0 | S6: 0 | T6: 0 | U6: 0 | V6: 0 | W6: 0 | X6: 0 | Y6: 0 | Z6: 0 | AA6: 0 | AB6: 0 | AC6: 0 | AD6: 0 | AE6: 0 | AF6: 0 | AG6: 0 | AH6: 0 | AI6: 0 | AJ6: 0 | AK6: 0 | AL6: 0
A7: 2 | B7: B | C7: 2|B | D7: My natural energy level at work is: | E7: 0 | F7: 0 | G7: 3 | H7: 0 | I7: 0 | J7: 0 | K7: 0.5 | L7: 0 | M7: 0 | N7: 0 | O7: 0.5 | P7: 0 | Q7: 0 | R7: 0 | S7: 0 | T7: 0 | U7: 0 | V7: 0 | W7: 0 | X7: 0 | Y7: 0 | Z7: 0 | AA7: 0 | AB7: 0 | AC7: 0 | AD7: 0 | AE7: 0 | AF7: 0 | AG7: 0 | AH7: 0 | AI7: 0 | AJ7: 0 | AK7: 0 | AL7: 0
A8: 2 | B8: C | C8: 2|C | D8: My natural energy level at work is: | E8: 0 | F8: 0 | G8: 0 | H8: 3 | I8: 0 | J8: 0 | K8: 0 | L8: 0.5 | M8: 0 | N8: 0 | O8: 0 | P8: 0.5 | Q8: 0 | R8: 0 | S8: 0 | T8: 0 | U8: 0 | V8: 0 | W8: 0 | X8: 0 | Y8: 0 | Z8: 0 | AA8: 0 | AB8: 0 | AC8: 0 | AD8: 0 | AE8: 0 | AF8: 0 | AG8: 0 | AH8: 0 | AI8: 0 | AJ8: 0 | AK8: 0 | AL8: 0
A9: 2 | B9: D | C9: 2|D | D9: My natural energy level at work is: | E9: 0 | F9: 0 | G9: 0 | H9: 0 | I9: 3 | J9: 0 | K9: 0 | L9: 0 | M9: 0.5 | N9: 0 | O9: 0 | P9: 0 | Q9: 0.5 | R9: 0 | S9: 0 | T9: 0 | U9: 0 | V9: 0 | W9: 0 | X9: 0 | Y9: 0 | Z9: 0 | AA9: 0 | AB9: 0 | AC9: 0 | AD9: 0 | AE9: 0 | AF9: 0 | AG9: 0 | AH9: 0 | AI9: 0 | AJ9: 0 | AK9: 0 | AL9: 0
A10: 3 | B10: A | C10: 3|A | D10: When priorities change suddenly: | E10: 0 | F10: 3 | G10: 0 | H10: 0 | I10: 0 | J10: 0.5 | K10: 0 | L10: 0 | M10: 0 | N10: 0.5 | O10: 0 | P10: 0 | Q10: 0 | R10: 0 | S10: 0 | T10: 0 | U10: 0 | V10: 0 | W10: 0 | X10: 0 | Y10: 0 | Z10: 0 | AA10: 0 | AB10: 0 | AC10: 0 | AD10: 0 | AE10: 0 | AF10: 0 | AG10: 0 | AH10: 0 | AI10: 0 | AJ10: 0 | AK10: 0 | AL10: 0
A11: 3 | B11: B | C11: 3|B | D11: When priorities change suddenly: | E11: 0 | F11: 0 | G11: 3 | H11: 0 | I11: 0 | J11: 0 | K11: 0.5 | L11: 0 | M11: 0 | N11: 0 | O11: 0.5 | P11: 0 | Q11: 0 | R11: 0 | S11: 0 | T11: 0 | U11: 0 | V11: 0 | W11: 0 | X11: 0 | Y11: 0 | Z11: 0 | AA11: 0 | AB11: 0 | AC11: 0 | AD11: 0 | AE11: 0 | AF11: 0 | AG11: 0 | AH11: 0 | AI11: 0 | AJ11: 0 | AK11: 0 | AL11: 0
A12: 3 | B12: C | C12: 3|C | D12: When priorities change suddenly: | E12: 0 | F12: 0 | G12: 0 | H12: 3 | I12: 0 | J12: 0 | K12: 0 | L12: 0.5 | M12: 0 | N12: 0 | O12: 0 | P12: 0.5 | Q12: 0 | R12: 0 | S12: 0 | T12: 0 | U12: 0 | V12: 0 | W12: 0 | X12: 0 | Y12: 0 | Z12: 0 | AA12: 0 | AB12: 0 | AC12: 0 | AD12: 0 | AE12: 0 | AF12: 0 | AG12: 0 | AH12: 0 | AI12: 0 | AJ12: 0 | AK12: 0 | AL12: 0
A13: 3 | B13: D | C13: 3|D | D13: When priorities change suddenly: | E13: 0 | F13: 0 | G13: 0 | H13: 0 | I13: 3 | J13: 0 | K13: 0 | L13: 0 | M13: 0.5 | N13: 0 | O13: 0 | P13: 0 | Q13: 0.5 | R13: 0 | S13: 0 | T13: 0 | U13: 0 | V13: 0 | W13: 0 | X13: 0 | Y13: 0 | Z13: 0 | AA13: 0 | AB13: 0 | AC13: 0 | AD13: 0 | AE13: 0 | AF13: 0 | AG13: 0 | AH13: 0 | AI13: 0 | AJ13: 0 | AK13: 0 | AL13: 0
... A321: 80 | B321: D | C321: 80|D | D321: When evaluating people’s performance I value most: | E321: 0 | F321: 0 | G321: 0 | H321: 0 | I321: 3 | J321: 0 | K321: 0 | L321: 0 | M321: 0.5 | N321: 0 | O321: 0 | P321: 0 | Q321: 0.5 | R321: 0 | S321: 0 | T321: 0 | U321: 0 | V321: 0 | W321: 0 | X321: 0 | Y321: 0 | Z321: 0 | AA321: 0 | AB321: 0 | AC321: 0 | AD321: 0 | AE321: 0 | AF321: 0 | AG321: 0 | AH321: 0 | AI321: 0 | AJ321: 0 | AK321: 0 | AL321: 0

Sheet Responses
A1: Question | B1: Section | C1: Question Text | D1: Response | E1: Selected Option | F1: Key | G1: Style_Driver | H1: Style_Influencer | I1: Style_Operator | J1: Style_Analyst | K1: Mot_Achievement | L1: Mot_Influence | M1: Mot_Stability | N1: Mot_Mastery | O1: Lead_Results | P1: Lead_Vision | Q1: Lead_People | R1: Lead_Process | S1: Conflict_Compete | T1: Conflict_Collaborate | U1: Conflict_Compromise | V1: Conflict_Accommodate | W1: Conflict_Avoid | X1: Culture_Market | Y1: Culture_Adhocracy | Z1: Culture_Clan | AA1: Culture_Hierarchy | AB1: Stress_Control | AC1: Stress_Scatter | AD1: Stress_Avoidance | AE1: Stress_Criticality | AF1: Decision_Agility | AG1: Decision_Consensus | AH1: Decision_Stability | AI1: Decision_Evidence | AJ1: Role_Commercial Leadership | AK1: Role_Business Development | AL1: Role_Operations Management | AM1: Role_Technical Specialist
A2: 1 | B2: Core Personality | C2: When beginning a new initiative, I usually: | E2: =IF(D2="","",INDEX(Questions!$D$2:$G$81,MATCH(A2,Questions!$A$2:$A$81,0),MATCH(D2,{"A","B","C","D"},0))) | F2: =A2&"|"&D2 -> 1| | G2: =IF($D2="","",SUMIFS(Weights!$F:$F,Weights!$C:$C,$F2)) | H2: =IF($D2="","",SUMIFS(Weights!$G:$G,Weights!$C:$C,$F2)) | I2: =IF($D2="","",SUMIFS(Weights!$H:$H,Weights!$C:$C,$F2)) | J2: =IF($D2="","",SUMIFS(Weights!$I:$I,Weights!$C:$C,$F2)) | K2: =IF($D2="","",SUMIFS(Weights!$J:$J,Weights!$C:$C,$F2)) | L2: =IF($D2="","",SUMIFS(Weights!$K:$K,Weights!$C:$C,$F2)) | M2: =IF($D2="","",SUMIFS(Weights!$L:$L,Weights!$C:$C,$F2)) | N2: =IF($D2="","",SUMIFS(Weights!$M:$M,Weights!$C:$C,$F2)) | O2: =IF($D2="","",SUMIFS(Weights!$N:$N,Weights!$C:$C,$F2)) | P2: =IF($D2="","",SUMIFS(Weights!$O:$O,Weights!$C:$C,$F2)) | Q2: =IF($D2="","",SUMIFS(Weights!$P:$P,Weights!$C:$C,$F2)) | R2: =IF($D2="","",SUMIFS(Weights!$Q:$Q,Weights!$C:$C,$F2)) | S2: =IF($D2="","",SUMIFS(Weights!$R:$R,Weights!$C:$C,$F2)) | T2: =IF($D2="","",SUMIFS(Weights!$S:$S,Weights!$C:$C,$F2)) | U2: =IF($D2="","",SUMIFS(Weights!$T:$T,Weights!$C:$C,$F2)) | V2: =IF($D2="","",SUMIFS(Weights!$U:$U,Weights!$C:$C,$F2)) | W2: =IF($D2="","",SUMIFS(Weights!$V:$V,Weights!$C:$C,$F2)) | X2: =IF($D2="","",SUMIFS(Weights!$W:$W,Weights!$C:$C,$F2)) | Y2: =IF($D2="","",SUMIFS(Weights!$X:$X,Weights!$C:$C,$F2)) | Z2: =IF($D2="","",SUMIFS(Weights!$Y:$Y,Weights!$C:$C,$F2)) | AA2: =IF($D2="","",SUMIFS(Weights!$Z:$Z,Weights!$C:$C,$F2)) | AB2: =IF($D2="","",SUMIFS(Weights!$AA:$AA,Weights!$C:$C,$F2)) | AC2: =IF($D2="","",SUMIFS(Weights!$AB:$AB,Weights!$C:$C,$F2)) | AD2: =IF($D2="","",SUMIFS(Weights!$AC:$AC,Weights!$C:$C,$F2)) | AE2: =IF($D2="","",SUMIFS(Weights!$AD:$AD,Weights!$C:$C,$F2)) | AF2: =IF($D2="","",SUMIFS(Weights!$AE:$AE,Weights!$C:$C,$F2)) | AG2: =IF($D2="","",SUMIFS(Weights!$AF:$AF,Weights!$C:$C,$F2)) | AH2: =IF($D2="","",SUMIFS(Weights!$AG:$AG,Weights!$C:$C,$F2)) | AI2: =IF($D2="","",SUMIFS(Weights!$AH:$AH,Weights!$C:$C,$F2)) | AJ2: =IF($D2="","",SUMIFS(Weights!$AI:$AI,Weights!$C:$C,$F2)) | AK2: =IF($D2="","",SUMIFS(Weights!$AJ:$AJ,Weights!$C:$C,$F2)) | AL2: =IF($D2="","",SUMIFS(Weights!$AK:$AK,Weights!$C:$C,$F2)) | AM2: =IF($D2="","",SUMIFS(Weights!$AL:$AL,Weights!$C:$C,$F2))
A3: 2 | B3: Core Personality | C3: My natural energy level at work is: | E3: =IF(D3="","",INDEX(Questions!$D$2:$G$81,MATCH(A3,Questions!$A$2:$A$81,0),MATCH(D3,{"A","B","C","D"},0))) | F3: =A3&"|"&D3 -> 2| | G3: =IF($D3="","",SUMIFS(Weights!$F:$F,Weights!$C:$C,$F3)) | H3: =IF($D3="","",SUMIFS(Weights!$G:$G,Weights!$C:$C,$F3)) | I3: =IF($D3="","",SUMIFS(Weights!$H:$H,Weights!$C:$C,$F3)) | J3: =IF($D3="","",SUMIFS(Weights!$I:$I,Weights!$C:$C,$F3)) | K3: =IF($D3="","",SUMIFS(Weights!$J:$J,Weights!$C:$C,$F3)) | L3: =IF($D3="","",SUMIFS(Weights!$K:$K,Weights!$C:$C,$F3)) | M3: =IF($D3="","",SUMIFS(Weights!$L:$L,Weights!$C:$C,$F3)) | N3: =IF($D3="","",SUMIFS(Weights!$M:$M,Weights!$C:$C,$F3)) | O3: =IF($D3="","",SUMIFS(Weights!$N:$N,Weights!$C:$C,$F3)) | P3: =IF($D3="","",SUMIFS(Weights!$O:$O,Weights!$C:$C,$F3)) | Q3: =IF($D3="","",SUMIFS(Weights!$P:$P,Weights!$C:$C,$F3)) | R3: =IF($D3="","",SUMIFS(Weights!$Q:$Q,Weights!$C:$C,$F3)) | S3: =IF($D3="","",SUMIFS(Weights!$R:$R,Weights!$C:$C,$F3)) | T3: =IF($D3="","",SUMIFS(Weights!$S:$S,Weights!$C:$C,$F3)) | U3: =IF($D3="","",SUMIFS(Weights!$T:$T,Weights!$C:$C,$F3)) | V3: =IF($D3="","",SUMIFS(Weights!$U:$U,Weights!$C:$C,$F3)) | W3: =IF($D3="","",SUMIFS(Weights!$V:$V,Weights!$C:$C,$F3)) | X3: =IF($D3="","",SUMIFS(Weights!$W:$W,Weights!$C:$C,$F3)) | Y3: =IF($D3="","",SUMIFS(Weights!$X:$X,Weights!$C:$C,$F3)) | Z3: =IF($D3="","",SUMIFS(Weights!$Y:$Y,Weights!$C:$C,$F3)) | AA3: =IF($D3="","",SUMIFS(Weights!$Z:$Z,Weights!$C:$C,$F3)) | AB3: =IF($D3="","",SUMIFS(Weights!$AA:$AA,Weights!$C:$C,$F3)) | AC3: =IF($D3="","",SUMIFS(Weights!$AB:$AB,Weights!$C:$C,$F3)) | AD3: =IF($D3="","",SUMIFS(Weights!$AC:$AC,Weights!$C:$C,$F3)) | AE3: =IF($D3="","",SUMIFS(Weights!$AD:$AD,Weights!$C:$C,$F3)) | AF3: =IF($D3="","",SUMIFS(Weights!$AE:$AE,Weights!$C:$C,$F3)) | AG3: =IF($D3="","",SUMIFS(Weights!$AF:$AF,Weights!$C:$C,$F3)) | AH3: =IF($D3="","",SUMIFS(Weights!$AG:$AG,Weights!$C:$C,$F3)) | AI3: =IF($D3="","",SUMIFS(Weights!$AH:$AH,Weights!$C:$C,$F3)) | AJ3: =IF($D3="","",SUMIFS(Weights!$AI:$AI,Weights!$C:$C,$F3)) | AK3: =IF($D3="","",SUMIFS(Weights!$AJ:$AJ,Weights!$C:$C,$F3)) | AL3: =IF($D3="","",SUMIFS(Weights!$AK:$AK,Weights!$C:$C,$F3)) | AM3: =IF($D3="","",SUMIFS(Weights!$AL:$AL,Weights!$C:$C,$F3))
A4: 3 | B4: Core Personality | C4: When priorities change suddenly: | E4: =IF(D4="","",INDEX(Questions!$D$2:$G$81,MATCH(A4,Questions!$A$2:$A$81,0),MATCH(D4,{"A","B","C","D"},0))) | F4: =A4&"|"&D4 -> 3| | G4: =IF($D4="","",SUMIFS(Weights!$F:$F,Weights!$C:$C,$F4)) | H4: =IF($D4="","",SUMIFS(Weights!$G:$G,Weights!$C:$C,$F4)) | I4: =IF($D4="","",SUMIFS(Weights!$H:$H,Weights!$C:$C,$F4)) | J4: =IF($D4="","",SUMIFS(Weights!$I:$I,Weights!$C:$C,$F4)) | K4: =IF($D4="","",SUMIFS(Weights!$J:$J,Weights!$C:$C,$F4)) | L4: =IF($D4="","",SUMIFS(Weights!$K:$K,Weights!$C:$C,$F4)) | M4: =IF($D4="","",SUMIFS(Weights!$L:$L,Weights!$C:$C,$F4)) | N4: =IF($D4="","",SUMIFS(Weights!$M:$M,Weights!$C:$C,$F4)) | O4: =IF($D4="","",SUMIFS(Weights!$N:$N,Weights!$C:$C,$F4)) | P4: =IF($D4="","",SUMIFS(Weights!$O:$O,Weights!$C:$C,$F4)) | Q4: =IF($D4="","",SUMIFS(Weights!$P:$P,Weights!$C:$C,$F4)) | R4: =IF($D4="","",SUMIFS(Weights!$Q:$Q,Weights!$C:$C,$F4)) | S4: =IF($D4="","",SUMIFS(Weights!$R:$R,Weights!$C:$C,$F4)) | T4: =IF($D4="","",SUMIFS(Weights!$S:$S,Weights!$C:$C,$F4)) | U4: =IF($D4="","",SUMIFS(Weights!$T:$T,Weights!$C:$C,$F4)) | V4: =IF($D4="","",SUMIFS(Weights!$U:$U,Weights!$C:$C,$F4)) | W4: =IF($D4="","",SUMIFS(Weights!$V:$V,Weights!$C:$C,$F4)) | X4: =IF($D4="","",SUMIFS(Weights!$W:$W,Weights!$C:$C,$F4)) | Y4: =IF($D4="","",SUMIFS(Weights!$X:$X,Weights!$C:$C,$F4)) | Z4: =IF($D4="","",SUMIFS(Weights!$Y:$Y,Weights!$C:$C,$F4)) | AA4: =IF($D4="","",SUMIFS(Weights!$Z:$Z,Weights!$C:$C,$F4)) | AB4: =IF($D4="","",SUMIFS(Weights!$AA:$AA,Weights!$C:$C,$F4)) | AC4: =IF($D4="","",SUMIFS(Weights!$AB:$AB,Weights!$C:$C,$F4)) | AD4: =IF($D4="","",SUMIFS(Weights!$AC:$AC,Weights!$C:$C,$F4)) | AE4: =IF($D4="","",SUMIFS(Weights!$AD:$AD,Weights!$C:$C,$F4)) | AF4: =IF($D4="","",SUMIFS(Weights!$AE:$AE,Weights!$C:$C,$F4)) | AG4: =IF($D4="","",SUMIFS(Weights!$AF:$AF,Weights!$C:$C,$F4)) | AH4: =IF($D4="","",SUMIFS(Weights!$AG:$AG,Weights!$C:$C,$F4)) | AI4: =IF($D4="","",SUMIFS(Weights!$AH:$AH,Weights!$C:$C,$F4)) | AJ4: =IF($D4="","",SUMIFS(Weights!$AI:$AI,Weights!$C:$C,$F4)) | AK4: =IF($D4="","",SUMIFS(Weights!$AJ:$AJ,Weights!$C:$C,$F4)) | AL4: =IF($D4="","",SUMIFS(Weights!$AK:$AK,Weights!$C:$C,$F4)) | AM4: =IF($D4="","",SUMIFS(Weights!$AL:$AL,Weights!$C:$C,$F4))
A5: 4 | B5: Core Personality | C5: I prefer tasks that are: | E5: =IF(D5="","",INDEX(Questions!$D$2:$G$81,MATCH(A5,Questions!$A$2:$A$81,0),MATCH(D5,{"A","B","C","D"},0))) | F5: =A5&"|"&D5 -> 4| | G5: =IF($D5="","",SUMIFS(Weights!$F:$F,Weights!$C:$C,$F5)) | H5: =IF($D5="","",SUMIFS(Weights!$G:$G,Weights!$C:$C,$F5)) | I5: =IF($D5="","",SUMIFS(Weights!$H:$H,Weights!$C:$C,$F5)) | J5: =IF($D5="","",SUMIFS(Weights!$I:$I,Weights!$C:$C,$F5)) | K5: =IF($D5="","",SUMIFS(Weights!$J:$J,Weights!$C:$C,$F5)) | L5: =IF($D5="","",SUMIFS(Weights!$K:$K,Weights!$C:$C,$F5)) | M5: =IF($D5="","",SUMIFS(Weights!$L:$L,Weights!$C:$C,$F5)) | N5: =IF($D5="","",SUMIFS(Weights!$M:$M,Weights!$C:$C,$F5)) | O5: =IF($D5="","",SUMIFS(Weights!$N:$N,Weights!$C:$C,$F5)) | P5: =IF($D5="","",SUMIFS(Weights!$O:$O,Weights!$C:$C,$F5)) | Q5: =IF($D5="","",SUMIFS(Weights!$P:$P,Weights!$C:$C,$F5)) | R5: =IF($D5="","",SUMIFS(Weights!$Q:$Q,Weights!$C:$C,$F5)) | S5: =IF($D5="","",SUMIFS(Weights!$R:$R,Weights!$C:$C,$F5)) | T5: =IF($D5="","",SUMIFS(Weights!$S:$S,Weights!$C:$C,$F5)) | U5: =IF($D5="","",SUMIFS(Weights!$T:$T,Weights!$C:$C,$F5)) | V5: =IF($D5="","",SUMIFS(Weights!$U:$U,Weights!$C:$C,$F5)) | W5: =IF($D5="","",SUMIFS(Weights!$V:$V,Weights!$C:$C,$F5)) | X5: =IF($D5="","",SUMIFS(Weights!$W:$W,Weights!$C:$C,$F5)) | Y5: =IF($D5="","",SUMIFS(Weights!$X:$X,Weights!$C:$C,$F5)) | Z5: =IF($D5="","",SUMIFS(Weights!$Y:$Y,Weights!$C:$C,$F5)) | AA5: =IF($D5="","",SUMIFS(Weights!$Z:$Z,Weights!$C:$C,$F5)) | AB5: =IF($D5="","",SUMIFS(Weights!$AA:$AA,Weights!$C:$C,$F5)) | AC5: =IF($D5="","",SUMIFS(Weights!$AB:$AB,Weights!$C:$C,$F5)) | AD5: =IF($D5="","",SUMIFS(Weights!$AC:$AC,Weights!$C:$C,$F5)) | AE5: =IF($D5="","",SUMIFS(Weights!$AD:$AD,Weights!$C:$C,$F5)) | AF5: =IF($D5="","",SUMIFS(Weights!$AE:$AE,Weights!$C:$C,$F5)) | AG5: =IF($D5="","",SUMIFS(Weights!$AF:$AF,Weights!$C:$C,$F5)) | AH5: =IF($D5="","",SUMIFS(Weights!$AG:$AG,Weights!$C:$C,$F5)) | AI5: =IF($D5="","",SUMIFS(Weights!$AH:$AH,Weights!$C:$C,$F5)) | AJ5: =IF($D5="","",SUMIFS(Weights!$AI:$AI,Weights!$C:$C,$F5)) | AK5: =IF($D5="","",SUMIFS(Weights!$AJ:$AJ,Weights!$C:$C,$F5)) | AL5: =IF($D5="","",SUMIFS(Weights!$AK:$AK,Weights!$C:$C,$F5)) | AM5: =IF($D5="","",SUMIFS(Weights!$AL:$AL,Weights!$C:$C,$F5))
A6: 5 | B6: Core Personality | C6: In uncertain situations I: | E6: =IF(D6="","",INDEX(Questions!$D$2:$G$81,MATCH(A6,Questions!$A$2:$A$81,0),MATCH(D6,{"A","B","C","D"},0))) | F6: =A6&"|"&D6 -> 5| | G6: =IF($D6="","",SUMIFS(Weights!$F:$F,Weights!$C:$C,$F6)) | H6: =IF($D6="","",SUMIFS(Weights!$G:$G,Weights!$C:$C,$F6)) | I6: =IF($D6="","",SUMIFS(Weights!$H:$H,Weights!$C:$C,$F6)) | J6: =IF($D6="","",SUMIFS(Weights!$I:$I,Weights!$C:$C,$F6)) | K6: =IF($D6="","",SUMIFS(Weights!$J:$J,Weights!$C:$C,$F6)) | L6: =IF($D6="","",SUMIFS(Weights!$K:$K,Weights!$C:$C,$F6)) | M6: =IF($D6="","",SUMIFS(Weights!$L:$L,Weights!$C:$C,$F6)) | N6: =IF($D6="","",SUMIFS(Weights!$M:$M,Weights!$C:$C,$F6)) | O6: =IF($D6="","",SUMIFS(Weights!$N:$N,Weights!$C:$C,$F6)) | P6: =IF($D6="","",SUMIFS(Weights!$O:$O,Weights!$C:$C,$F6)) | Q6: =IF($D6="","",SUMIFS(Weights!$P:$P,Weights!$C:$C,$F6)) | R6: =IF($D6="","",SUMIFS(Weights!$Q:$Q,Weights!$C:$C,$F6)) | S6: =IF($D6="","",SUMIFS(Weights!$R:$R,Weights!$C:$C,$F6)) | T6: =IF($D6="","",SUMIFS(Weights!$S:$S,Weights!$C:$C,$F6)) | U6: =IF($D6="","",SUMIFS(Weights!$T:$T,Weights!$C:$C,$F6)) | V6: =IF($D6="","",SUMIFS(Weights!$U:$U,Weights!$C:$C,$F6)) | W6: =IF($D6="","",SUMIFS(Weights!$V:$V,Weights!$C:$C,$F6)) | X6: =IF($D6="","",SUMIFS(Weights!$W:$W,Weights!$C:$C,$F6)) | Y6: =IF($D6="","",SUMIFS(Weights!$X:$X,Weights!$C:$C,$F6)) | Z6: =IF($D6="","",SUMIFS(Weights!$Y:$Y,Weights!$C:$C,$F6)) | AA6: =IF($D6="","",SUMIFS(Weights!$Z:$Z,Weights!$C:$C,$F6)) | AB6: =IF($D6="","",SUMIFS(Weights!$AA:$AA,Weights!$C:$C,$F6)) | AC6: =IF($D6="","",SUMIFS(Weights!$AB:$AB,Weights!$C:$C,$F6)) | AD6: =IF($D6="","",SUMIFS(Weights!$AC:$AC,Weights!$C:$C,$F6)) | AE6: =IF($D6="","",SUMIFS(Weights!$AD:$AD,Weights!$C:$C,$F6)) | AF6: =IF($D6="","",SUMIFS(Weights!$AE:$AE,Weights!$C:$C,$F6)) | AG6: =IF($D6="","",SUMIFS(Weights!$AF:$AF,Weights!$C:$C,$F6)) | AH6: =IF($D6="","",SUMIFS(Weights!$AG:$AG,Weights!$C:$C,$F6)) | AI6: =IF($D6="","",SUMIFS(Weights!$AH:$AH,Weights!$C:$C,$F6)) | AJ6: =IF($D6="","",SUMIFS(Weights!$AI:$AI,Weights!$C:$C,$F6)) | AK6: =IF($D6="","",SUMIFS(Weights!$AJ:$AJ,Weights!$C:$C,$F6)) | AL6: =IF($D6="","",SUMIFS(Weights!$AK:$AK,Weights!$C:$C,$F6)) | AM6: =IF($D6="","",SUMIFS(Weights!$AL:$AL,Weights!$C:$C,$F6))
A7: 6 | B7: Core Personality | C7: My attention to detail is: | E7: =IF(D7="","",INDEX(Questions!$D$2:$G$81,MATCH(A7,Questions!$A$2:$A$81,0),MATCH(D7,{"A","B","C","D"},0))) | F7: =A7&"|"&D7 -> 6| | G7: =IF($D7="","",SUMIFS(Weights!$F:$F,Weights!$C:$C,$F7)) | H7: =IF($D7="","",SUMIFS(Weights!$G:$G,Weights!$C:$C,$F7)) | I7: =IF($D7="","",SUMIFS(Weights!$H:$H,Weights!$C:$C,$F7)) | J7: =IF($D7="","",SUMIFS(Weights!$I:$I,Weights!$C:$C,$F7)) | K7: =IF($D7="","",SUMIFS(Weights!$J:$J,Weights!$C:$C,$F7)) | L7: =IF($D7="","",SUMIFS(Weights!$K:$K,Weights!$C:$C,$F7)) | M7: =IF($D7="","",SUMIFS(Weights!$L:$L,Weights!$C:$C,$F7)) | N7: =IF($D7="","",SUMIFS(Weights!$M:$M,Weights!$C:$C,$F7)) | O7: =IF($D7="","",SUMIFS(Weights!$N:$N,Weights!$C:$C,$F7)) | P7: =IF($D7="","",SUMIFS(Weights!$O:$O,Weights!$C:$C,$F7)) | Q7: =IF($D7="","",SUMIFS(Weights!$P:$P,Weights!$C:$C,$F7)) | R7: =IF($D7="","",SUMIFS(Weights!$Q:$Q,Weights!$C:$C,$F7)) | S7: =IF($D7="","",SUMIFS(Weights!$R:$R,Weights!$C:$C,$F7)) | T7: =IF($D7="","",SUMIFS(Weights!$S:$S,Weights!$C:$C,$F7)) | U7: =IF($D7="","",SUMIFS(Weights!$T:$T,Weights!$C:$C,$F7)) | V7: =IF($D7="","",SUMIFS(Weights!$U:$U,Weights!$C:$C,$F7)) | W7: =IF($D7="","",SUMIFS(Weights!$V:$V,Weights!$C:$C,$F7)) | X7: =IF($D7="","",SUMIFS(Weights!$W:$W,Weights!$C:$C,$F7)) | Y7: =IF($D7="","",SUMIFS(Weights!$X:$X,Weights!$C:$C,$F7)) | Z7: =IF($D7="","",SUMIFS(Weights!$Y:$Y,Weights!$C:$C,$F7)) | AA7: =IF($D7="","",SUMIFS(Weights!$Z:$Z,Weights!$C:$C,$F7)) | AB7: =IF($D7="","",SUMIFS(Weights!$AA:$AA,Weights!$C:$C,$F7)) | AC7: =IF($D7="","",SUMIFS(Weights!$AB:$AB,Weights!$C:$C,$F7)) | AD7: =IF($D7="","",SUMIFS(Weights!$AC:$AC,Weights!$C:$C,$F7)) | AE7: =IF($D7="","",SUMIFS(Weights!$AD:$AD,Weights!$C:$C,$F7)) | AF7: =IF($D7="","",SUMIFS(Weights!$AE:$AE,Weights!$C:$C,$F7)) | AG7: =IF($D7="","",SUMIFS(Weights!$AF:$AF,Weights!$C:$C,$F7)) | AH7: =IF($D7="","",SUMIFS(Weights!$AG:$AG,Weights!$C:$C,$F7)) | AI7: =IF($D7="","",SUMIFS(Weights!$AH:$AH,Weights!$C:$C,$F7)) | AJ7: =IF($D7="","",SUMIFS(Weights!$AI:$AI,Weights!$C:$C,$F7)) | AK7: =IF($D7="","",SUMIFS(Weights!$AJ:$AJ,Weights!$C:$C,$F7)) | AL7: =IF($D7="","",SUMIFS(Weights!$AK:$AK,Weights!$C:$C,$F7)) | AM7: =IF($D7="","",SUMIFS(Weights!$AL:$AL,Weights!$C:$C,$F7))
A8: 7 | B8: Core Personality | C8: Feedback typically: | E8: =IF(D8="","",INDEX(Questions!$D$2:$G$81,MATCH(A8,Questions!$A$2:$A$81,0),MATCH(D8,{"A","B","C","D"},0))) | F8: =A8&"|"&D8 -> 7| | G8: =IF($D8="","",SUMIFS(Weights!$F:$F,Weights!$C:$C,$F8)) | H8: =IF($D8="","",SUMIFS(Weights!$G:$G,Weights!$C:$C,$F8)) | I8: =IF($D8="","",SUMIFS(Weights!$H:$H,Weights!$C:$C,$F8)) | J8: =IF($D8="","",SUMIFS(Weights!$I:$I,Weights!$C:$C,$F8)) | K8: =IF($D8="","",SUMIFS(Weights!$J:$J,Weights!$C:$C,$F8)) | L8: =IF($D8="","",SUMIFS(Weights!$K:$K,Weights!$C:$C,$F8)) | M8: =IF($D8="","",SUMIFS(Weights!$L:$L,Weights!$C:$C,$F8)) | N8: =IF($D8="","",SUMIFS(Weights!$M:$M,Weights!$C:$C,$F8)) | O8: =IF($D8="","",SUMIFS(Weights!$N:$N,Weights!$C:$C,$F8)) | P8: =IF($D8="","",SUMIFS(Weights!$O:$O,Weights!$C:$C,$F8)) | Q8: =IF($D8="","",SUMIFS(Weights!$P:$P,Weights!$C:$C,$F8)) | R8: =IF($D8="","",SUMIFS(Weights!$Q:$Q,Weights!$C:$C,$F8)) | S8: =IF($D8="","",SUMIFS(Weights!$R:$R,Weights!$C:$C,$F8)) | T8: =IF($D8="","",SUMIFS(Weights!$S:$S,Weights!$C:$C,$F8)) | U8: =IF($D8="","",SUMIFS(Weights!$T:$T,Weights!$C:$C,$F8)) | V8: =IF($D8="","",SUMIFS(Weights!$U:$U,Weights!$C:$C,$F8)) | W8: =IF($D8="","",SUMIFS(Weights!$V:$V,Weights!$C:$C,$F8)) | X8: =IF($D8="","",SUMIFS(Weights!$W:$W,Weights!$C:$C,$F8)) | Y8: =IF($D8="","",SUMIFS(Weights!$X:$X,Weights!$C:$C,$F8)) | Z8: =IF($D8="","",SUMIFS(Weights!$Y:$Y,Weights!$C:$C,$F8)) | AA8: =IF($D8="","",SUMIFS(Weights!$Z:$Z,Weights!$C:$C,$F8)) | AB8: =IF($D8="","",SUMIFS(Weights!$AA:$AA,Weights!$C:$C,$F8)) | AC8: =IF($D8="","",SUMIFS(Weights!$AB:$AB,Weights!$C:$C,$F8)) | AD8: =IF($D8="","",SUMIFS(Weights!$AC:$AC,Weights!$C:$C,$F8)) | AE8: =IF($D8="","",SUMIFS(Weights!$AD:$AD,Weights!$C:$C,$F8)) | AF8: =IF($D8="","",SUMIFS(Weights!$AE:$AE,Weights!$C:$C,$F8)) | AG8: =IF($D8="","",SUMIFS(Weights!$AF:$AF,Weights!$C:$C,$F8)) | AH8: =IF($D8="","",SUMIFS(Weights!$AG:$AG,Weights!$C:$C,$F8)) | AI8: =IF($D8="","",SUMIFS(Weights!$AH:$AH,Weights!$C:$C,$F8)) | AJ8: =IF($D8="","",SUMIFS(Weights!$AI:$AI,Weights!$C:$C,$F8)) | AK8: =IF($D8="","",SUMIFS(Weights!$AJ:$AJ,Weights!$C:$C,$F8)) | AL8: =IF($D8="","",SUMIFS(Weights!$AK:$AK,Weights!$C:$C,$F8)) | AM8: =IF($D8="","",SUMIFS(Weights!$AL:$AL,Weights!$C:$C,$F8))
A9: 8 | B9: Core Personality | C9: My decision-making style is: | E9: =IF(D9="","",INDEX(Questions!$D$2:$G$81,MATCH(A9,Questions!$A$2:$A$81,0),MATCH(D9,{"A","B","C","D"},0))) | F9: =A9&"|"&D9 -> 8| | G9: =IF($D9="","",SUMIFS(Weights!$F:$F,Weights!$C:$C,$F9)) | H9: =IF($D9="","",SUMIFS(Weights!$G:$G,Weights!$C:$C,$F9)) | I9: =IF($D9="","",SUMIFS(Weights!$H:$H,Weights!$C:$C,$F9)) | J9: =IF($D9="","",SUMIFS(Weights!$I:$I,Weights!$C:$C,$F9)) | K9: =IF($D9="","",SUMIFS(Weights!$J:$J,Weights!$C:$C,$F9)) | L9: =IF($D9="","",SUMIFS(Weights!$K:$K,Weights!$C:$C,$F9)) | M9: =IF($D9="","",SUMIFS(Weights!$L:$L,Weights!$C:$C,$F9)) | N9: =IF($D9="","",SUMIFS(Weights!$M:$M,Weights!$C:$C,$F9)) | O9: =IF($D9="","",SUMIFS(Weights!$N:$N,Weights!$C:$C,$F9)) | P9: =IF($D9="","",SUMIFS(Weights!$O:$O,Weights!$C:$C,$F9)) | Q9: =IF($D9="","",SUMIFS(Weights!$P:$P,Weights!$C:$C,$F9)) | R9: =IF($D9="","",SUMIFS(Weights!$Q:$Q,Weights!$C:$C,$F9)) | S9: =IF($D9="","",SUMIFS(Weights!$R:$R,Weights!$C:$C,$F9)) | T9: =IF($D9="","",SUMIFS(Weights!$S:$S,Weights!$C:$C,$F9)) | U9: =IF($D9="","",SUMIFS(Weights!$T:$T,Weights!$C:$C,$F9)) | V9: =IF($D9="","",SUMIFS(Weights!$U:$U,Weights!$C:$C,$F9)) | W9: =IF($D9="","",SUMIFS(Weights!$V:$V,Weights!$C:$C,$F9)) | X9: =IF($D9="","",SUMIFS(Weights!$W:$W,Weights!$C:$C,$F9)) | Y9: =IF($D9="","",SUMIFS(Weights!$X:$X,Weights!$C:$C,$F9)) | Z9: =IF($D9="","",SUMIFS(Weights!$Y:$Y,Weights!$C:$C,$F9)) | AA9: =IF($D9="","",SUMIFS(Weights!$Z:$Z,Weights!$C:$C,$F9)) | AB9: =IF($D9="","",SUMIFS(Weights!$AA:$AA,Weights!$C:$C,$F9)) | AC9: =IF($D9="","",SUMIFS(Weights!$AB:$AB,Weights!$C:$C,$F9)) | AD9: =IF($D9="","",SUMIFS(Weights!$AC:$AC,Weights!$C:$C,$F9)) | AE9: =IF($D9="","",SUMIFS(Weights!$AD:$AD,Weights!$C:$C,$F9)) | AF9: =IF($D9="","",SUMIFS(Weights!$AE:$AE,Weights!$C:$C,$F9)) | AG9: =IF($D9="","",SUMIFS(Weights!$AF:$AF,Weights!$C:$C,$F9)) | AH9: =IF($D9="","",SUMIFS(Weights!$AG:$AG,Weights!$C:$C,$F9)) | AI9: =IF($D9="","",SUMIFS(Weights!$AH:$AH,Weights!$C:$C,$F9)) | AJ9: =IF($D9="","",SUMIFS(Weights!$AI:$AI,Weights!$C:$C,$F9)) | AK9: =IF($D9="","",SUMIFS(Weights!$AJ:$AJ,Weights!$C:$C,$F9)) | AL9: =IF($D9="","",SUMIFS(Weights!$AK:$AK,Weights!$C:$C,$F9)) | AM9: =IF($D9="","",SUMIFS(Weights!$AL:$AL,Weights!$C:$C,$F9))
A10: 9 | B10: Behaviour Style | C10: In meetings I tend to: | E10: =IF(D10="","",INDEX(Questions!$D$2:$G$81,MATCH(A10,Questions!$A$2:$A$81,0),MATCH(D10,{"A","B","C","D"},0))) | F10: =A10&"|"&D10 -> 9| | G10: =IF($D10="","",SUMIFS(Weights!$F:$F,Weights!$C:$C,$F10)) | H10: =IF($D10="","",SUMIFS(Weights!$G:$G,Weights!$C:$C,$F10)) | I10: =IF($D10="","",SUMIFS(Weights!$H:$H,Weights!$C:$C,$F10)) | J10: =IF($D10="","",SUMIFS(Weights!$I:$I,Weights!$C:$C,$F10)) | K10: =IF($D10="","",SUMIFS(Weights!$J:$J,Weights!$C:$C,$F10)) | L10: =IF($D10="","",SUMIFS(Weights!$K:$K,Weights!$C:$C,$F10)) | M10: =IF($D10="","",SUMIFS(Weights!$L:$L,Weights!$C:$C,$F10)) | N10: =IF($D10="","",SUMIFS(Weights!$M:$M,Weights!$C:$C,$F10)) | O10: =IF($D10="","",SUMIFS(Weights!$N:$N,Weights!$C:$C,$F10)) | P10: =IF($D10="","",SUMIFS(Weights!$O:$O,Weights!$C:$C,$F10)) | Q10: =IF($D10="","",SUMIFS(Weights!$P:$P,Weights!$C:$C,$F10)) | R10: =IF($D10="","",SUMIFS(Weights!$Q:$Q,Weights!$C:$C,$F10)) | S10: =IF($D10="","",SUMIFS(Weights!$R:$R,Weights!$C:$C,$F10)) | T10: =IF($D10="","",SUMIFS(Weights!$S:$S,Weights!$C:$C,$F10)) | U10: =IF($D10="","",SUMIFS(Weights!$T:$T,Weights!$C:$C,$F10)) | V10: =IF($D10="","",SUMIFS(Weights!$U:$U,Weights!$C:$C,$F10)) | W10: =IF($D10="","",SUMIFS(Weights!$V:$V,Weights!$C:$C,$F10)) | X10: =IF($D10="","",SUMIFS(Weights!$W:$W,Weights!$C:$C,$F10)) | Y10: =IF($D10="","",SUMIFS(Weights!$X:$X,Weights!$C:$C,$F10)) | Z10: =IF($D10="","",SUMIFS(Weights!$Y:$Y,Weights!$C:$C,$F10)) | AA10: =IF($D10="","",SUMIFS(Weights!$Z:$Z,Weights!$C:$C,$F10)) | AB10: =IF($D10="","",SUMIFS(Weights!$AA:$AA,Weights!$C:$C,$F10)) | AC10: =IF($D10="","",SUMIFS(Weights!$AB:$AB,Weights!$C:$C,$F10)) | AD10: =IF($D10="","",SUMIFS(Weights!$AC:$AC,Weights!$C:$C,$F10)) | AE10: =IF($D10="","",SUMIFS(Weights!$AD:$AD,Weights!$C:$C,$F10)) | AF10: =IF($D10="","",SUMIFS(Weights!$AE:$AE,Weights!$C:$C,$F10)) | AG10: =IF($D10="","",SUMIFS(Weights!$AF:$AF,Weights!$C:$C,$F10)) | AH10: =IF($D10="","",SUMIFS(Weights!$AG:$AG,Weights!$C:$C,$F10)) | AI10: =IF($D10="","",SUMIFS(Weights!$AH:$AH,Weights!$C:$C,$F10)) | AJ10: =IF($D10="","",SUMIFS(Weights!$AI:$AI,Weights!$C:$C,$F10)) | AK10: =IF($D10="","",SUMIFS(Weights!$AJ:$AJ,Weights!$C:$C,$F10)) | AL10: =IF($D10="","",SUMIFS(Weights!$AK:$AK,Weights!$C:$C,$F10)) | AM10: =IF($D10="","",SUMIFS(Weights!$AL:$AL,Weights!$C:$C,$F10))
A11: 10 | B11: Behaviour Style | C11: My communication is: | E11: =IF(D11="","",INDEX(Questions!$D$2:$G$81,MATCH(A11,Questions!$A$2:$A$81,0),MATCH(D11,{"A","B","C","D"},0))) | F11: =A11&"|"&D11 -> 10| | G11: =IF($D11="","",SUMIFS(Weights!$F:$F,Weights!$C:$C,$F11)) | H11: =IF($D11="","",SUMIFS(Weights!$G:$G,Weights!$C:$C,$F11)) | I11: =IF($D11="","",SUMIFS(Weights!$H:$H,Weights!$C:$C,$F11)) | J11: =IF($D11="","",SUMIFS(Weights!$I:$I,Weights!$C:$C,$F11)) | K11: =IF($D11="","",SUMIFS(Weights!$J:$J,Weights!$C:$C,$F11)) | L11: =IF($D11="","",SUMIFS(Weights!$K:$K,Weights!$C:$C,$F11)) | M11: =IF($D11="","",SUMIFS(Weights!$L:$L,Weights!$C:$C,$F11)) | N11: =IF($D11="","",SUMIFS(Weights!$M:$M,Weights!$C:$C,$F11)) | O11: =IF($D11="","",SUMIFS(Weights!$N:$N,Weights!$C:$C,$F11)) | P11: =IF($D11="","",SUMIFS(Weights!$O:$O,Weights!$C:$C,$F11)) | Q11: =IF($D11="","",SUMIFS(Weights!$P:$P,Weights!$C:$C,$F11)) | R11: =IF($D11="","",SUMIFS(Weights!$Q:$Q,Weights!$C:$C,$F11)) | S11: =IF($D11="","",SUMIFS(Weights!$R:$R,Weights!$C:$C,$F11)) | T11: =IF($D11="","",SUMIFS(Weights!$S:$S,Weights!$C:$C,$F11)) | U11: =IF($D11="","",SUMIFS(Weights!$T:$T,Weights!$C:$C,$F11)) | V11: =IF($D11="","",SUMIFS(Weights!$U:$U,Weights!$C:$C,$F11)) | W11: =IF($D11="","",SUMIFS(Weights!$V:$V,Weights!$C:$C,$F11)) | X11: =IF($D11="","",SUMIFS(Weights!$W:$W,Weights!$C:$C,$F11)) | Y11: =IF($D11="","",SUMIFS(Weights!$X:$X,Weights!$C:$C,$F11)) | Z11: =IF($D11="","",SUMIFS(Weights!$Y:$Y,Weights!$C:$C,$F11)) | AA11: =IF($D11="","",SUMIFS(Weights!$Z:$Z,Weights!$C:$C,$F11)) | AB11: =IF($D11="","",SUMIFS(Weights!$AA:$AA,Weights!$C:$C,$F11)) | AC11: =IF($D11="","",SUMIFS(Weights!$AB:$AB,Weights!$C:$C,$F11)) | AD11: =IF($D11="","",SUMIFS(Weights!$AC:$AC,Weights!$C:$C,$F11)) | AE11: =IF($D11="","",SUMIFS(Weights!$AD:$AD,Weights!$C:$C,$F11)) | AF11: =IF($D11="","",SUMIFS(Weights!$AE:$AE,Weights!$C:$C,$F11)) | AG11: =IF($D11="","",SUMIFS(Weights!$AF:$AF,Weights!$C:$C,$F11)) | AH11: =IF($D11="","",SUMIFS(Weights!$AG:$AG,Weights!$C:$C,$F11)) | AI11: =IF($D11="","",SUMIFS(Weights!$AH:$AH,Weights!$C:$C,$F11)) | AJ11: =IF($D11="","",SUMIFS(Weights!$AI:$AI,Weights!$C:$C,$F11)) | AK11: =IF($D11="","",SUMIFS(Weights!$AJ:$AJ,Weights!$C:$C,$F11)) | AL11: =IF($D11="","",SUMIFS(Weights!$AK:$AK,Weights!$C:$C,$F11)) | AM11: =IF($D11="","",SUMIFS(Weights!$AL:$AL,Weights!$C:$C,$F11))
A12: 11 | B12: Behaviour Style | C12: When leading a project I: | E12: =IF(D12="","",INDEX(Questions!$D$2:$G$81,MATCH(A12,Questions!$A$2:$A$81,0),MATCH(D12,{"A","B","C","D"},0))) | F12: =A12&"|"&D12 -> 11| | G12: =IF($D12="","",SUMIFS(Weights!$F:$F,Weights!$C:$C,$F12)) | H12: =IF($D12="","",SUMIFS(Weights!$G:$G,Weights!$C:$C,$F12)) | I12: =IF($D12="","",SUMIFS(Weights!$H:$H,Weights!$C:$C,$F12)) | J12: =IF($D12="","",SUMIFS(Weights!$I:$I,Weights!$C:$C,$F12)) | K12: =IF($D12="","",SUMIFS(Weights!$J:$J,Weights!$C:$C,$F12)) | L12: =IF($D12="","",SUMIFS(Weights!$K:$K,Weights!$C:$C,$F12)) | M12: =IF($D12="","",SUMIFS(Weights!$L:$L,Weights!$C:$C,$F12)) | N12: =IF($D12="","",SUMIFS(Weights!$M:$M,Weights!$C:$C,$F12)) | O12: =IF($D12="","",SUMIFS(Weights!$N:$N,Weights!$C:$C,$F12)) | P12: =IF($D12="","",SUMIFS(Weights!$O:$O,Weights!$C:$C,$F12)) | Q12: =IF($D12="","",SUMIFS(Weights!$P:$P,Weights!$C:$C,$F12)) | R12: =IF($D12="","",SUMIFS(Weights!$Q:$Q,Weights!$C:$C,$F12)) | S12: =IF($D12="","",SUMIFS(Weights!$R:$R,Weights!$C:$C,$F12)) | T12: =IF($D12="","",SUMIFS(Weights!$S:$S,Weights!$C:$C,$F12)) | U12: =IF($D12="","",SUMIFS(Weights!$T:$T,Weights!$C:$C,$F12)) | V12: =IF($D12="","",SUMIFS(Weights!$U:$U,Weights!$C:$C,$F12)) | W12: =IF($D12="","",SUMIFS(Weights!$V:$V,Weights!$C:$C,$F12)) | X12: =IF($D12="","",SUMIFS(Weights!$W:$W,Weights!$C:$C,$F12)) | Y12: =IF($D12="","",SUMIFS(Weights!$X:$X,Weights!$C:$C,$F12)) | Z12: =IF($D12="","",SUMIFS(Weights!$Y:$Y,Weights!$C:$C,$F12)) | AA12: =IF($D12="","",SUMIFS(Weights!$Z:$Z,Weights!$C:$C,$F12)) | AB12: =IF($D12="","",SUMIFS(Weights!$AA:$AA,Weights!$C:$C,$F12)) | AC12: =IF($D12="","",SUMIFS(Weights!$AB:$AB,Weights!$C:$C,$F12)) | AD12: =IF($D12="","",SUMIFS(Weights!$AC:$AC,Weights!$C:$C,$F12)) | AE12: =IF($D12="","",SUMIFS(Weights!$AD:$AD,Weights!$C:$C,$F12)) | AF12: =IF($D12="","",SUMIFS(Weights!$AE:$AE,Weights!$C:$C,$F12)) | AG12: =IF($D12="","",SUMIFS(Weights!$AF:$AF,Weights!$C:$C,$F12)) | AH12: =IF($D12="","",SUMIFS(Weights!$AG:$AG,Weights!$C:$C,$F12)) | AI12: =IF($D12="","",SUMIFS(Weights!$AH:$AH,Weights!$C:$C,$F12)) | AJ12: =IF($D12="","",SUMIFS(Weights!$AI:$AI,Weights!$C:$C,$F12)) | AK12: =IF($D12="","",SUMIFS(Weights!$AJ:$AJ,Weights!$C:$C,$F12)) | AL12: =IF($D12="","",SUMIFS(Weights!$AK:$AK,Weights!$C:$C,$F12)) | AM12: =IF($D12="","",SUMIFS(Weights!$AL:$AL,Weights!$C:$C,$F12))
A13: 12 | B13: Behaviour Style | C13: Under time pressure I: | E13: =IF(D13="","",INDEX(Questions!$D$2:$G$81,MATCH(A13,Questions!$A$2:$A$81,0),MATCH(D13,{"A","B","C","D"},0))) | F13: =A13&"|"&D13 -> 12| | G13: =IF($D13="","",SUMIFS(Weights!$F:$F,Weights!$C:$C,$F13)) | H13: =IF($D13="","",SUMIFS(Weights!$G:$G,Weights!$C:$C,$F13)) | I13: =IF($D13="","",SUMIFS(Weights!$H:$H,Weights!$C:$C,$F13)) | J13: =IF($D13="","",SUMIFS(Weights!$I:$I,Weights!$C:$C,$F13)) | K13: =IF($D13="","",SUMIFS(Weights!$J:$J,Weights!$C:$C,$F13)) | L13: =IF($D13="","",SUMIFS(Weights!$K:$K,Weights!$C:$C,$F13)) | M13: =IF($D13="","",SUMIFS(Weights!$L:$L,Weights!$C:$C,$F13)) | N13: =IF($D13="","",SUMIFS(Weights!$M:$M,Weights!$C:$C,$F13)) | O13: =IF($D13="","",SUMIFS(Weights!$N:$N,Weights!$C:$C,$F13)) | P13: =IF($D13="","",SUMIFS(Weights!$O:$O,Weights!$C:$C,$F13)) | Q13: =IF($D13="","",SUMIFS(Weights!$P:$P,Weights!$C:$C,$F13)) | R13: =IF($D13="","",SUMIFS(Weights!$Q:$Q,Weights!$C:$C,$F13)) | S13: =IF($D13="","",SUMIFS(Weights!$R:$R,Weights!$C:$C,$F13)) | T13: =IF($D13="","",SUMIFS(Weights!$S:$S,Weights!$C:$C,$F13)) | U13: =IF($D13="","",SUMIFS(Weights!$T:$T,Weights!$C:$C,$F13)) | V13: =IF($D13="","",SUMIFS(Weights!$U:$U,Weights!$C:$C,$F13)) | W13: =IF($D13="","",SUMIFS(Weights!$V:$V,Weights!$C:$C,$F13)) | X13: =IF($D13="","",SUMIFS(Weights!$W:$W,Weights!$C:$C,$F13)) | Y13: =IF($D13="","",SUMIFS(Weights!$X:$X,Weights!$C:$C,$F13)) | Z13: =IF($D13="","",SUMIFS(Weights!$Y:$Y,Weights!$C:$C,$F13)) | AA13: =IF($D13="","",SUMIFS(Weights!$Z:$Z,Weights!$C:$C,$F13)) | AB13: =IF($D13="","",SUMIFS(Weights!$AA:$AA,Weights!$C:$C,$F13)) | AC13: =IF($D13="","",SUMIFS(Weights!$AB:$AB,Weights!$C:$C,$F13)) | AD13: =IF($D13="","",SUMIFS(Weights!$AC:$AC,Weights!$C:$C,$F13)) | AE13: =IF($D13="","",SUMIFS(Weights!$AD:$AD,Weights!$C:$C,$F13)) | AF13: =IF($D13="","",SUMIFS(Weights!$AE:$AE,Weights!$C:$C,$F13)) | AG13: =IF($D13="","",SUMIFS(Weights!$AF:$AF,Weights!$C:$C,$F13)) | AH13: =IF($D13="","",SUMIFS(Weights!$AG:$AG,Weights!$C:$C,$F13)) | AI13: =IF($D13="","",SUMIFS(Weights!$AH:$AH,Weights!$C:$C,$F13)) | AJ13: =IF($D13="","",SUMIFS(Weights!$AI:$AI,Weights!$C:$C,$F13)) | AK13: =IF($D13="","",SUMIFS(Weights!$AJ:$AJ,Weights!$C:$C,$F13)) | AL13: =IF($D13="","",SUMIFS(Weights!$AK:$AK,Weights!$C:$C,$F13)) | AM13: =IF($D13="","",SUMIFS(Weights!$AL:$AL,Weights!$C:$C,$F13))
... A81: 80 | B81: Behavioural Integrity & Nuance | C81: When evaluating people’s performance I value most: | E81: =IF(D81="","",INDEX(Questions!$D$2:$G$81,MATCH(A81,Questions!$A$2:$A$81,0),MATCH(D81,{"A","B","C","D"},0))) | F81: =A81&"|"&D81 -> 80| | G81: =IF($D81="","",SUMIFS(Weights!$F:$F,Weights!$C:$C,$F81)) | H81: =IF($D81="","",SUMIFS(Weights!$G:$G,Weights!$C:$C,$F81)) | I81: =IF($D81="","",SUMIFS(Weights!$H:$H,Weights!$C:$C,$F81)) | J81: =IF($D81="","",SUMIFS(Weights!$I:$I,Weights!$C:$C,$F81)) | K81: =IF($D81="","",SUMIFS(Weights!$J:$J,Weights!$C:$C,$F81)) | L81: =IF($D81="","",SUMIFS(Weights!$K:$K,Weights!$C:$C,$F81)) | M81: =IF($D81="","",SUMIFS(Weights!$L:$L,Weights!$C:$C,$F81)) | N81: =IF($D81="","",SUMIFS(Weights!$M:$M,Weights!$C:$C,$F81)) | O81: =IF($D81="","",SUMIFS(Weights!$N:$N,Weights!$C:$C,$F81)) | P81: =IF($D81="","",SUMIFS(Weights!$O:$O,Weights!$C:$C,$F81)) | Q81: =IF($D81="","",SUMIFS(Weights!$P:$P,Weights!$C:$C,$F81)) | R81: =IF($D81="","",SUMIFS(Weights!$Q:$Q,Weights!$C:$C,$F81)) | S81: =IF($D81="","",SUMIFS(Weights!$R:$R,Weights!$C:$C,$F81)) | T81: =IF($D81="","",SUMIFS(Weights!$S:$S,Weights!$C:$C,$F81)) | U81: =IF($D81="","",SUMIFS(Weights!$T:$T,Weights!$C:$C,$F81)) | V81: =IF($D81="","",SUMIFS(Weights!$U:$U,Weights!$C:$C,$F81)) | W81: =IF($D81="","",SUMIFS(Weights!$V:$V,Weights!$C:$C,$F81)) | X81: =IF($D81="","",SUMIFS(Weights!$W:$W,Weights!$C:$C,$F81)) | Y81: =IF($D81="","",SUMIFS(Weights!$X:$X,Weights!$C:$C,$F81)) | Z81: =IF($D81="","",SUMIFS(Weights!$Y:$Y,Weights!$C:$C,$F81)) | AA81: =IF($D81="","",SUMIFS(Weights!$Z:$Z,Weights!$C:$C,$F81)) | AB81: =IF($D81="","",SUMIFS(Weights!$AA:$AA,Weights!$C:$C,$F81)) | AC81: =IF($D81="","",SUMIFS(Weights!$AB:$AB,Weights!$C:$C,$F81)) | AD81: =IF($D81="","",SUMIFS(Weights!$AC:$AC,Weights!$C:$C,$F81)) | AE81: =IF($D81="","",SUMIFS(Weights!$AD:$AD,Weights!$C:$C,$F81)) | AF81: =IF($D81="","",SUMIFS(Weights!$AE:$AE,Weights!$C:$C,$F81)) | AG81: =IF($D81="","",SUMIFS(Weights!$AF:$AF,Weights!$C:$C,$F81)) | AH81: =IF($D81="","",SUMIFS(Weights!$AG:$AG,Weights!$C:$C,$F81)) | AI81: =IF($D81="","",SUMIFS(Weights!$AH:$AH,Weights!$C:$C,$F81)) | AJ81: =IF($D81="","",SUMIFS(Weights!$AI:$AI,Weights!$C:$C,$F81)) | AK81: =IF($D81="","",SUMIFS(Weights!$AJ:$AJ,Weights!$C:$C,$F81)) | AL81: =IF($D81="","",SUMIFS(Weights!$AK:$AK,Weights!$C:$C,$F81)) | AM81: =IF($D81="","",SUMIFS(Weights!$AL:$AL,Weights!$C:$C,$F81))

Sheet Results
A1: Sonartra Signals Results
A3: Culture Target Inputs (%) | B3: Market | C3: Adhocracy | D3: Clan | E3: Hierarchy
A4: Target % | B4: 25 | C4: 25 | D4: 25 | E4: 25
F7: Headline Outputs
A8: Behaviour Style | F8: Dominant Behaviour Style | G8: =INDEX($A$9:$A$12,MATCH(MAX($B$9:$B$12),$B$9:$B$12,0)) -> Style Driver
A9: Style Driver | B9: =SUM(Responses!$G$2:$G$81) -> 0 | C9: =IF(SUM($B$9:$B$12)=0,0,B9/SUM($B$9:$B$12)) -> 0 | D9: =IF(C9<=Thresholds!$B$2,"Low",IF(C9<=Thresholds!$C$2,"Medium","High")) -> Low | F9: Secondary Behaviour Style | G9: =INDEX($A$9:$A$12,MATCH(LARGE($B$9:$B$12,2),$B$9:$B$12,0)) -> Style Driver
A10: Style Influencer | B10: =SUM(Responses!$H$2:$H$81) -> 0 | C10: =IF(SUM($B$9:$B$12)=0,0,B10/SUM($B$9:$B$12)) -> 0 | D10: =IF(C10<=Thresholds!$B$2,"Low",IF(C10<=Thresholds!$C$2,"Medium","High")) -> Low | F10: Archetype | G10: =IFERROR(INDEX(Archetypes!$C$2:$C$13,MATCH(SUBSTITUTE(G8,"Style ","")&"|"&SUBSTITUTE(G9,"Style ",""),Archetypes!$E$2:$E$13,0)),"Review mapping") -> Review mapping
A11: Style Operator | B11: =SUM(Responses!$I$2:$I$81) -> 0 | C11: =IF(SUM($B$9:$B$12)=0,0,B11/SUM($B$9:$B$12)) -> 0 | D11: =IF(C11<=Thresholds!$B$2,"Low",IF(C11<=Thresholds!$C$2,"Medium","High")) -> Low | F11: Motivational Core | G11: =INDEX($A$16:$A$19,MATCH(MAX($B$16:$B$19),$B$16:$B$19,0)) -> Mot Achievement
A12: Style Analyst | B12: =SUM(Responses!$J$2:$J$81) -> 0 | C12: =IF(SUM($B$9:$B$12)=0,0,B12/SUM($B$9:$B$12)) -> 0 | D12: =IF(C12<=Thresholds!$B$2,"Low",IF(C12<=Thresholds!$C$2,"Medium","High")) -> Low | F12: Leadership Architecture | G12: =INDEX($A$23:$A$26,MATCH(MAX($B$23:$B$26),$B$23:$B$26,0)) -> Lead Results
F13: Conflict Mode | G13: =INDEX($A$30:$A$34,MATCH(MAX($B$30:$B$34),$B$30:$B$34,0)) -> Conflict Compete
F14: Stress Derailer Risk | G14: =INDEX($A$45:$A$48,MATCH(MAX($B$45:$B$48),$B$45:$B$48,0)) -> Stress Control
A15: Motivators | F15: Culture Preference | G15: =INDEX($A$38:$A$41,MATCH(MAX($B$38:$B$41),$B$38:$B$41,0)) -> Culture Market
A16: Mot Achievement | B16: =SUM(Responses!$K$2:$K$81) -> 0 | C16: =IF(SUM($B$16:$B$19)=0,0,B16/SUM($B$16:$B$19)) -> 0 | D16: =IF(C16<=Thresholds!$B$2,"Low",IF(C16<=Thresholds!$C$2,"Medium","High")) -> Low | F16: Decision Orientation | G16: =INDEX($A$52:$A$55,MATCH(MAX($B$52:$B$55),$B$52:$B$55,0)) -> Decision Agility
A17: Mot Influence | B17: =SUM(Responses!$L$2:$L$81) -> 0 | C17: =IF(SUM($B$16:$B$19)=0,0,B17/SUM($B$16:$B$19)) -> 0 | D17: =IF(C17<=Thresholds!$B$2,"Low",IF(C17<=Thresholds!$C$2,"Medium","High")) -> Low | F17: Role Alignment | G17: =INDEX($A$59:$A$62,MATCH(MAX($B$59:$B$62),$B$59:$B$62,0)) -> Commercial Leadership
A18: Mot Stability | B18: =SUM(Responses!$M$2:$M$81) -> 0 | C18: =IF(SUM($B$16:$B$19)=0,0,B18/SUM($B$16:$B$19)) -> 0 | D18: =IF(C18<=Thresholds!$B$2,"Low",IF(C18<=Thresholds!$C$2,"Medium","High")) -> Low | F18: Leadership Potential Score | G18: =ROUND(AVERAGE($C$23:$C$26,$C$9:$C$12),3) -> 0
A19: Mot Mastery | B19: =SUM(Responses!$N$2:$N$81) -> 0 | C19: =IF(SUM($B$16:$B$19)=0,0,B19/SUM($B$16:$B$19)) -> 0 | D19: =IF(C19<=Thresholds!$B$2,"Low",IF(C19<=Thresholds!$C$2,"Medium","High")) -> Low | F19: Culture Tension Index | G19: =AVERAGE(ABS($C$38-B4/100),ABS($C$39-C4/100),ABS($C$40-D4/100),ABS($C$41-E4/100)) -> 0.25
A22: Leadership
A23: Lead Results | B23: =SUM(Responses!$O$2:$O$81) -> 0 | C23: =IF(SUM($B$23:$B$26)=0,0,B23/SUM($B$23:$B$26)) -> 0 | D23: =IF(C23<=Thresholds!$B$2,"Low",IF(C23<=Thresholds!$C$2,"Medium","High")) -> Low
A24: Lead Vision | B24: =SUM(Responses!$P$2:$P$81) -> 0 | C24: =IF(SUM($B$23:$B$26)=0,0,B24/SUM($B$23:$B$26)) -> 0 | D24: =IF(C24<=Thresholds!$B$2,"Low",IF(C24<=Thresholds!$C$2,"Medium","High")) -> Low
A25: Lead People | B25: =SUM(Responses!$Q$2:$Q$81) -> 0 | C25: =IF(SUM($B$23:$B$26)=0,0,B25/SUM($B$23:$B$26)) -> 0 | D25: =IF(C25<=Thresholds!$B$2,"Low",IF(C25<=Thresholds!$C$2,"Medium","High")) -> Low
A26: Lead Process | B26: =SUM(Responses!$R$2:$R$81) -> 0 | C26: =IF(SUM($B$23:$B$26)=0,0,B26/SUM($B$23:$B$26)) -> 0 | D26: =IF(C26<=Thresholds!$B$2,"Low",IF(C26<=Thresholds!$C$2,"Medium","High")) -> Low
A29: Conflict
A30: Conflict Compete | B30: =SUM(Responses!$S$2:$S$81) -> 0 | C30: =IF(SUM($B$30:$B$34)=0,0,B30/SUM($B$30:$B$34)) -> 0 | D30: =IF(C30<=Thresholds!$B$2,"Low",IF(C30<=Thresholds!$C$2,"Medium","High")) -> Low
A31: Conflict Collaborate | B31: =SUM(Responses!$T$2:$T$81) -> 0 | C31: =IF(SUM($B$30:$B$34)=0,0,B31/SUM($B$30:$B$34)) -> 0 | D31: =IF(C31<=Thresholds!$B$2,"Low",IF(C31<=Thresholds!$C$2,"Medium","High")) -> Low
A32: Conflict Compromise | B32: =SUM(Responses!$U$2:$U$81) -> 0 | C32: =IF(SUM($B$30:$B$34)=0,0,B32/SUM($B$30:$B$34)) -> 0 | D32: =IF(C32<=Thresholds!$B$2,"Low",IF(C32<=Thresholds!$C$2,"Medium","High")) -> Low
A33: Conflict Accommodate | B33: =SUM(Responses!$V$2:$V$81) -> 0 | C33: =IF(SUM($B$30:$B$34)=0,0,B33/SUM($B$30:$B$34)) -> 0 | D33: =IF(C33<=Thresholds!$B$2,"Low",IF(C33<=Thresholds!$C$2,"Medium","High")) -> Low
A34: Conflict Avoid | B34: =SUM(Responses!$W$2:$W$81) -> 0 | C34: =IF(SUM($B$30:$B$34)=0,0,B34/SUM($B$30:$B$34)) -> 0 | D34: =IF(C34<=Thresholds!$B$2,"Low",IF(C34<=Thresholds!$C$2,"Medium","High")) -> Low
A37: Culture
A38: Culture Market | B38: =SUM(Responses!$X$2:$X$81) -> 0 | C38: =IF(SUM($B$38:$B$41)=0,0,B38/SUM($B$38:$B$41)) -> 0 | D38: =IF(C38<=Thresholds!$B$2,"Low",IF(C38<=Thresholds!$C$2,"Medium","High")) -> Low
A39: Culture Adhocracy | B39: =SUM(Responses!$Y$2:$Y$81) -> 0 | C39: =IF(SUM($B$38:$B$41)=0,0,B39/SUM($B$38:$B$41)) -> 0 | D39: =IF(C39<=Thresholds!$B$2,"Low",IF(C39<=Thresholds!$C$2,"Medium","High")) -> Low
A40: Culture Clan | B40: =SUM(Responses!$Z$2:$Z$81) -> 0 | C40: =IF(SUM($B$38:$B$41)=0,0,B40/SUM($B$38:$B$41)) -> 0 | D40: =IF(C40<=Thresholds!$B$2,"Low",IF(C40<=Thresholds!$C$2,"Medium","High")) -> Low
A41: Culture Hierarchy | B41: =SUM(Responses!$AA$2:$AA$81) -> 0 | C41: =IF(SUM($B$38:$B$41)=0,0,B41/SUM($B$38:$B$41)) -> 0 | D41: =IF(C41<=Thresholds!$B$2,"Low",IF(C41<=Thresholds!$C$2,"Medium","High")) -> Low
A44: Stress
A45: Stress Control | B45: =SUM(Responses!$AB$2:$AB$81) -> 0 | C45: =IF(SUM($B$45:$B$48)=0,0,B45/SUM($B$45:$B$48)) -> 0 | D45: =IF(C45<=Thresholds!$B$2,"Low",IF(C45<=Thresholds!$C$2,"Medium","High")) -> Low
A46: Stress Scatter | B46: =SUM(Responses!$AC$2:$AC$81) -> 0 | C46: =IF(SUM($B$45:$B$48)=0,0,B46/SUM($B$45:$B$48)) -> 0 | D46: =IF(C46<=Thresholds!$B$2,"Low",IF(C46<=Thresholds!$C$2,"Medium","High")) -> Low
A47: Stress Avoidance | B47: =SUM(Responses!$AD$2:$AD$81) -> 0 | C47: =IF(SUM($B$45:$B$48)=0,0,B47/SUM($B$45:$B$48)) -> 0 | D47: =IF(C47<=Thresholds!$B$2,"Low",IF(C47<=Thresholds!$C$2,"Medium","High")) -> Low
A48: Stress Criticality | B48: =SUM(Responses!$AE$2:$AE$81) -> 0 | C48: =IF(SUM($B$45:$B$48)=0,0,B48/SUM($B$45:$B$48)) -> 0 | D48: =IF(C48<=Thresholds!$B$2,"Low",IF(C48<=Thresholds!$C$2,"Medium","High")) -> Low
A51: Decision & Risk
A52: Decision Agility | B52: =SUM(Responses!$AF$2:$AF$81) -> 0 | C52: =IF(SUM($B$52:$B$55)=0,0,B52/SUM($B$52:$B$55)) -> 0 | D52: =IF(C52<=Thresholds!$B$2,"Low",IF(C52<=Thresholds!$C$2,"Medium","High")) -> Low
A53: Decision Consensus | B53: =SUM(Responses!$AG$2:$AG$81) -> 0 | C53: =IF(SUM($B$52:$B$55)=0,0,B53/SUM($B$52:$B$55)) -> 0 | D53: =IF(C53<=Thresholds!$B$2,"Low",IF(C53<=Thresholds!$C$2,"Medium","High")) -> Low
...

Sheet Output
A1: Sonartra Signals – Generated Individual Report
A2: Archetype | B2: =Results!G10 -> Review mapping
A3: Core Identity | B3: =IFERROR(INDEX(Archetypes!$D$2:$D$13,MATCH(B2,Archetypes!$C$2:$C$13,0)),"Review archetype mapping.") -> Review archetype mapping.
A4: How You Operate | B4: =_xludf.TEXTJOIN(" ",TRUE,IF(Results!$D$16="High",INDEX('Sentence Library'!$D$2:$D$26,MATCH("How You Operate|Achievement|High",'Sentence Library'!$E$2:$E$26,0)),""),IF(Results!$D$17="High",INDEX('Sentence Library'!$D$2:$D$26,MATCH("How You Operate|Influence|High",'Sentence Library'!$E$2:$E$26,0)),""),IF(Results!$D$18="High",INDEX('Sentence Library'!$D$2:$D$26,MATCH("How You Operate|Stability|High",'Sentence Library'!$E$2:$E$26,0)),""),IF(Results!$D$19="High",INDEX('Sentence Library'!$D$2:$D$26,MATCH("How You Operate|Mastery|High",'Sentence Library'!$E$2:$E$26,0)),"")) -> #NAME?
A5: Leadership Profile | B5: =_xludf.TEXTJOIN(" ",TRUE,IF(Results!$D$23="High",INDEX('Sentence Library'!$D$2:$D$26,MATCH("Leadership|Results|High",'Sentence Library'!$E$2:$E$26,0)),""),IF(Results!$D$24="High",INDEX('Sentence Library'!$D$2:$D$26,MATCH("Leadership|Vision|High",'Sentence Library'!$E$2:$E$26,0)),""),IF(Results!$D$25="High",INDEX('Sentence Library'!$D$2:$D$26,MATCH("Leadership|People|High",'Sentence Library'!$E$2:$E$26,0)),""),IF(Results!$D$26="High",INDEX('Sentence Library'!$D$2:$D$26,MATCH("Leadership|Process|High",'Sentence Library'!$E$2:$E$26,0)),"")) -> #NAME?
A6: Conflict Style | B6: =_xludf.TEXTJOIN(" ",TRUE,IF(Results!$D$30="High",INDEX('Sentence Library'!$D$2:$D$26,MATCH("Conflict|Compete|High",'Sentence Library'!$E$2:$E$26,0)),""),IF(Results!$D$31="High",INDEX('Sentence Library'!$D$2:$D$26,MATCH("Conflict|Collaborate|High",'Sentence Library'!$E$2:$E$26,0)),""),IF(Results!$D$32="High",INDEX('Sentence Library'!$D$2:$D$26,MATCH("Conflict|Compromise|High",'Sentence Library'!$E$2:$E$26,0)),""),IF(Results!$D$33="High",INDEX('Sentence Library'!$D$2:$D$26,MATCH("Conflict|Accommodate|High",'Sentence Library'!$E$2:$E$26,0)),""),IF(Results!$D$34="High",INDEX('Sentence Library'!$D$2:$D$26,MATCH("Conflict|Avoid|High",'Sentence Library'!$E$2:$E$26,0)),"")) -> #NAME?
A7: Pressure Pattern | B7: =_xludf.TEXTJOIN(" ",TRUE,IF(Results!$D$45="High",INDEX('Sentence Library'!$D$2:$D$26,MATCH("Pressure|Control|High",'Sentence Library'!$E$2:$E$26,0)),""),IF(Results!$D$46="High",INDEX('Sentence Library'!$D$2:$D$26,MATCH("Pressure|Scatter|High",'Sentence Library'!$E$2:$E$26,0)),""),IF(Results!$D$47="High",INDEX('Sentence Library'!$D$2:$D$26,MATCH("Pressure|Avoidance|High",'Sentence Library'!$E$2:$E$26,0)),""),IF(Results!$D$48="High",INDEX('Sentence Library'!$D$2:$D$26,MATCH("Pressure|Criticality|High",'Sentence Library'!$E$2:$E$26,0)),"")) -> #NAME?
A8: Culture Fit | B8: =_xludf.TEXTJOIN(" ",TRUE,IF(Results!$D$38="High",INDEX('Sentence Library'!$D$2:$D$26,MATCH("Culture|Market|High",'Sentence Library'!$E$2:$E$26,0)),""),IF(Results!$D$39="High",INDEX('Sentence Library'!$D$2:$D$26,MATCH("Culture|Adhocracy|High",'Sentence Library'!$E$2:$E$26,0)),""),IF(Results!$D$40="High",INDEX('Sentence Library'!$D$2:$D$26,MATCH("Culture|Clan|High",'Sentence Library'!$E$2:$E$26,0)),""),IF(Results!$D$41="High",INDEX('Sentence Library'!$D$2:$D$26,MATCH("Culture|Hierarchy|High",'Sentence Library'!$E$2:$E$26,0)),"")) -> #NAME?
A9: Decision Orientation | B9: =Results!G16 -> Decision Agility
A10: Role Alignment | B10: =Results!G17 -> Commercial Leadership
A11: Leadership Potential Score | B11: =Results!G18 -> 0
A12: Culture Tension Index | B12: =Results!G19 -> 0.25
